<mujoco>
    <worldbody>
        <light diffuse="0.7 0.7 0.7" pos="0 0 2" dir="0 -1 0"/>
        <geom type="plane" size="1 1 0.1" rgba="1 1 1 1"/>
        <!-- green box -->
        <body pos="0 0 0">
            <joint type="free"/>
            
            <geom type="box" size="0.1 0.2 0.3" rgba="0.3 0.9 0 1"/>
            <body pos="-0.2 0 0.4">
                <joint name="whitejoint" type="hinge" axis="0 1 0" pos="0.1 0 -0.1"/>
                <geom type="box" size="0.1 0.2 0.1" rgba="1 1 1 1"/>
            </body>
            <body pos="0.3 0 0">
                <joint name="bluejoint" type="hinge" axis="1 0 0" pos="0 0 0"/>
                <geom type="box" size="0.1 0.2 0.3" rgba="0 0.2 0.9 1"/>
                <body pos="0.2 0 0.4">
                    <joint name="yellowjoint" type="hinge" axis="0 1 0" pos="-0.1 0 -0.1"/>
                    <geom type="box" size="0.1 0.2 0.1" rgba="1 1 0 1"/>
                </body>
            </body>
        </body>
    </worldbody>
    <actuator>
        <motor joint="bluejoint" name="bluej"/>
        <motor joint="whitejoint" name="whitej"/>
        <motor joint="yellowjoint" name="yellowj"/>
    </actuator>
</mujoco>