<mujoco>
    <option gravity="0 0 -9.81"/>
    <worldbody>
        <light diffuse="0.8 0.8 0.8" pos="0 0 2" dir="0 0 -1"/>
        <geom type="plane" size="1 1 0.1" rgba="1 1 1 1"/>
        <!-- Crab Main Body -->
        <body name="crab_body" pos="0 0 1">
            <joint name="crab_body" type="free"/>
            <geom type="cylinder" size="0.1 0.2" rgba="0.5 0.1 0.5 1" euler="0 90 0" mass="15"/> <!-- Changed to cylinder -->

            <!-- Front Left Leg -->
            <body name="front_left_leg" pos="-0.15 -0.2 0" euler="-90 0 -90">
                <joint name="fl1" pos="0 0 0.1 " type="hinge" axis="0 1 0" range="-45 45"/>
                <geom type="cylinder" size="0.03 0.1" rgba="0 0 0.6 1"/>
                <body pos="0 0 -0.18">
                    <joint name="fl2" pos="0 0 0.08" type="hinge" axis="0 1 0" range="-45 45"/>
                    <geom type="cylinder" size="0.02 0.08" rgba="0.5 0.3 0.1 1"/>
                </body>
            </body>

            <!-- Front Right Leg -->
            <body name="front_right_leg" pos="-0.15 0.2 0" euler="-90 0 -90">
                <joint name="fr1" pos="0 0 -0.1" type="hinge" axis="0 1 0" range="-45 45"/>
                <geom type="cylinder" size="0.03 0.1" rgba="0 0 0.6 1"/>
                <body pos="0 0 0.18">
                    <joint name="fr2" pos="0 0 -0.08" type="hinge" axis="0 1 0" range="-45 45"/>
                    <geom type="cylinder" size="0.02 0.08" rgba="0.5 0.3 0.1 1"/>
                </body>
            </body>

            <!-- Back Left Leg -->
            <body name="back_left_leg" pos="0.15 -0.2 0" euler="-90 0 -90">
                <joint name="bl1" pos="0 0 0.1" type="hinge" axis="0 1 0" range="-45 45"/>
                <geom type="cylinder" size="0.03 0.1" rgba="0 0 0.6 1"/>
                <body pos="0 0 -0.18">
                    <joint name="bl2" pos="0 0 0.08" type="hinge" axis="0 1 0" range="-45 45"/>
                    <geom type="cylinder" size="0.02 0.08" rgba="0.5 0.3 0.1 1"/>
                </body>
            </body>

            <!-- Back Right Leg -->
            <body name="back_right_leg" pos="0.15 0.2 0" euler="-90 0 -90">
                <joint name="br1" pos="0 0 -0.1" type="hinge" axis="0 1 0" range="-45 45"/>
                <geom type="cylinder" size="0.03 0.1" rgba="0 0 0.6 1"/>
                <body pos="0 0 0.18">
                    <joint name="br2" pos="0 0 -0.08" type="hinge" axis="0 1 0" range="-45 45"/>
                    <geom type="cylinder" size="0.02 0.08" rgba="0.5 0.3 0.1 1"/>
                </body>
            </body>
        </body>
    </worldbody>
    <actuator>
        <motor joint="fl1" name="fl1j"/>
        <motor joint="fl2" name="fl2j"/>
        <motor joint="bl1" name="bl1j"/>
        <motor joint="bl2" name="bl2j"/>
        <motor joint="fr1" name="fr1j"/>
        <motor joint="fr2" name="fr2j"/>
        <motor joint="br1" name="br1j"/>
        <motor joint="br2" name="br2j"/>
    </actuator>
</mujoco>