<mujoco>
    <option gravity="0 0 -9.81"/>
    <worldbody>
        <light diffuse="0.8 0.8 0.8" pos="0 0 8" dir="0 0 -1"/>
        <geom type="plane" size="3 3 0.1" rgba="1 1 1 1"/>
        <!-- Main Body -->
        <body name="main_body" pos="0 0 2">
            <joint name="main_body" type="free"/>
            <geom type="cylinder" size="0.1 0.2" rgba="0.5 0.1 0.5 1" euler="90 0 90" mass="15"/> <!-- Changed to cylinder -->
            <!-- lightgreen Leg -->
            <body name="leg1" pos="-0.15 -0.1 0.1" euler="0 90 0">
                <joint name="leg1-1" pos="0 0 0.1 " type="hinge" axis="0 1 0" range="-45 45"/>
                <geom type="cylinder" size="0.03 0.1" rgba="0 1 0.6 1"/>
                <body pos="0 0 -0.18">
                    <joint name="leg1-2" pos="0 0 0.08" type="hinge" axis="0 1 0" range="-45 45"/>
                    <geom type="cylinder" size="0.02 0.08" rgba="0.5 0.3 0.1 1"/>
                </body>
            </body>

            <!-- hotpink Leg -->
            <body name="leg2" pos="-0.15 0.1 0.1" euler="0 90 0">
                <joint name="leg2-1" pos="0 0 0.1" type="hinge" axis="0 1 0" range="-45 45"/>
                <geom type="cylinder" size="0.03 0.1" rgba="1 0 0.6 1"/>
                <body pos="0 0 -0.18">
                    <joint name="leg2-2" pos="0 0 0.08" type="hinge" axis="0 1 0" range="-45 45"/>
                    <geom type="cylinder" size="0.02 0.08" rgba="0.5 0.3 0.1 1"/>
                </body>
            </body>

            <!-- Green Leg -->
            <body name="leg3" pos="0.15 -0.1 0.1" euler="0 -90 0">
                <joint name="leg3-1" pos="0 0 0.1" type="hinge" axis="0 1 0" range="-45 45"/>
                <geom type="cylinder" size="0.03 0.1" rgba="0 0.3 0.1 1"/>
                <body pos="0 0 -0.18">
                    <joint name="leg3-2" pos="0 0 0.08" type="hinge" axis="0 1 0" range="-45 45"/>
                    <geom type="cylinder" size="0.02 0.08" rgba="0.5 0.3 0.1 1"/>
                </body>
            </body>

            <!-- Back Right Leg -->
            <body name="leg4" pos="0.15 0.1 0.1" euler="0 -90 0">
                <joint name="leg4-1" pos="0 0 0.1" type="hinge" axis="0 1 0" range="-45 45"/>
                <geom type="cylinder" size="0.03 0.1" rgba="0 0 0.6 1"/>
                <body pos="0 0 -0.18">
                    <joint name="leg4-2" pos="0 0 0.08" type="hinge" axis="0 1 0" range="-45 45"/>
                    <geom type="cylinder" size="0.02 0.08" rgba="0.5 0.3 0.1 1"/>
                </body>
            </body>
        </body>

        


        <!-- second body -->






        <body name="main_body2" pos="1 1 2">
            <joint name="main_body2" type="free"/>
            <geom type="box" size="0.05 0.3 0.05" rgba="0.1 0.1 0.1 1" mass="15"/> <!-- Changed to cylinder -->

            <!-- Yellow Leg -->
            <body name="front_left_leg2" pos="-0.15 -0.2 0" euler="0 90 0">
                <joint name="fl1-2" pos="0 0 0.1 " type="hinge" axis="0 1 0" range="-45 45"/>
                <geom type="cylinder" size="0.03 0.1" rgba="1 1 0.6 1"/>
                <body pos="0 0 -0.18">
                    <joint name="fl2-2" pos="0 0 0.08" type="hinge" axis="0 1 0" range="-45 45"/>
                    <geom type="cylinder" size="0.02 0.2" rgba="0.5 0.3 0.1 1"/>
                </body>
            </body>

            <!-- Pink Leg -->
            <body name="front_right_leg2" pos="-0.15 0.2 0" euler="0 90 0">
                <joint name="fr1-2" pos="0 0 0.1" type="hinge" axis="0 1 0" range="-45 45"/>
                <geom type="cylinder" size="0.03 0.1" rgba="1 0 0.6 1"/>
                <body pos="0 0 -0.18">
                    <joint name="fr2-2" pos="0 0 0.08" type="hinge" axis="0 1 0" range="-45 45"/>
                    <geom type="cylinder" size="0.02 0.2" rgba="0.5 0.3 0.1 1"/>
                </body>
            </body>

            <!-- Blue Leg -->
            <body name="back_left_leg2" pos="0.15 -0.2 0" euler="0 -90 0">
                <joint name="bl1-2" pos="0 0 0.1" type="hinge" axis="0 1 0" range="-45 45"/>
                <geom type="cylinder" size="0.03 0.1" rgba="0 0 0.6 1"/>
                <body pos="0 0 -0.18">
                    <joint name="bl2-2" pos="0 0 0.08" type="hinge" axis="0 1 0" range="-45 45"/>
                    <geom type="cylinder" size="0.02 0.2" rgba="0.5 0.3 0.1 1"/>
                </body>
            </body>

            <!-- Teal Leg -->
            <body name="back_right_leg2" pos="0.15 0.2 0" euler="0 -90 0">
                <joint name="br1-2" pos="0 0 0.1" type="hinge" axis="0 1 0" range="-45 45"/>
                <geom type="cylinder" size="0.03 0.1" rgba="0 0.6 0.6 1"/>
                <body pos="0 0 -0.18">
                    <joint name="br2-2" pos="0 0 0.08" type="hinge" axis="0 1 0" range="-45 45"/>
                    <geom type="cylinder" size="0.02 0.2" rgba="0.5 0.3 0.1 1"/>
                </body>
            </body>
        </body>







        <!-- third body -->




        <body name="main_body3" pos="-1 0 2">
            <joint name="main_body3" type="free"/>
            <geom type="cylinder" size="0.1 0.2" rgba="0.5 0.1 0.5 1" euler="90 0 90" mass="3"/> <!-- Changed to cylinder -->
            <!-- lightgreen Leg -->
            <!-- <body name="good" pos="-0.15 -0.1 0.1" euler="0 90 0"> -->
            <!-- <body name="good" pos="-0.15 -0.1 0.1" euler="0 45 0"> -->
            <body name="good" pos="-0.15 -0.1 0.1">
                <joint name="good1-1" pos="0 0 -0.1 " type="hinge" axis="0 1 0" range="-45 45"/>
                <geom type="box" size="0.03 0.03 0.1" rgba="0 1 0.6 1" mass="1"/>
                <body pos="0.01 0 -0.18">
                    <joint name="good1-2" pos="0 0 0.08" type="hinge" axis="0 1 0" range="-45 45"/>
                    <geom type="cylinder" size="0.1 0.08" rgba="0.5 0.3 0.1 1" mass="30"/>
                </body>
            </body>

            <!-- hotpink Leg -->
            <!-- <body name="good2" pos="-0.15 0.1 0.1" euler="0 90 0"> -->
            <!-- <body name="good2" pos="-0.15 0.1 0.1" euler = "0 45 0"> -->
            <body name="good2" pos="-0.15 0.1 0.1">
                <joint name="good2-1" pos="0 0 -0.1" type="hinge" axis="0 1 0" range="-45 45"/>
                <geom type="box" size="0.03 0.03 0.1" rgba="1 0 0.6 1" mass="1"/>
                <body pos="0.01 0 -0.18">
                    <joint name="good2-2" pos="0 0 0.08" type="hinge" axis="0 1 0" range="-45 45"/>
                    <geom type="cylinder" size="0.1 0.08" rgba="0.5 0.3 0.1 1" mass="30"/>
                </body>
            </body>

            <!-- Green Leg -->
            <!-- <body name="good3" pos="0.15 -0.1 0.1" euler="0 -90 0"> -->
            <!-- <body name="good3" pos="0.15 -0.1 0.1" euler="0 -45 0"> -->
            <body name="good3" pos="0.15 -0.1 0.1">
                <joint name="good3-1" pos="0 0 -0.1" type="hinge" axis="0 1 0" range="-45 45"/>
                <geom type="box" size="0.03 0.03 0.1" rgba="0 0.3 0.1 1" mass="1"/>
                <body pos="-0.01 0 -0.18">
                    <joint name="good3-2" pos="0 0 0.08" type="hinge" axis="0 1 0" range="-45 45"/>
                    <geom type="cylinder" size="0.1 0.08" rgba="0.5 0.3 0.1 1" mass="30"/>
                </body>
            </body>

            <!-- Blue Leg -->
            <!-- <body name="good4" pos="0.15 0.1 0.1" euler="0 -90 0"> -->
            <!-- <body name="good4" pos="0.15 0.1 0.1" euler="0 -45 0"> -->
            <body name="good4" pos="0.15 0.1 0.1">
                <joint name="good4-1" pos="0 0 -0.1" type="hinge" axis="0 1 0" range="-45 45"/>
                <geom type="box" size="0.03 0.03 0.1" rgba="0 0 0.6 1" mass="1"/>
                <body pos="-0.01 0 -0.18">
                    <joint name="good4-2" pos="0 0 0.08" type="hinge" axis="0 1 0" range="-45 45"/>
                    <geom type="cylinder" size="0.1 0.08" rgba="0.5 0.3 0.1 1" mass="30"/>
                </body>
            </body>
        </body>




        <!-- fourth body -->





        <body name="main_body4" pos="-1 1 2">
            <joint name="main_body4" type="free"/>
            <geom type="sphere" size="0.1" rgba="0.5 0.1 0.5 1" euler="90 0 90" mass="15"/> <!-- Changed to cylinder -->
            <!-- lightgreen Leg -->
            <body name="sphere" pos="-0.15 -0.1 0.1" euler="0 90 0">
                <joint name="sphere1-1" pos="0 0 0.1 " type="hinge" axis="0 1 0" range="-45 45"/>
                <geom type="cylinder" size="0.03 0.1" rgba="0 1 0.6 1"/>
                <body pos="0 0 -0.18">
                    <joint name="sphere1-2" pos="0 0 0.08" type="hinge" axis="0 1 0" range="-45 45"/>
                    <geom type="cylinder" size="0.02 0.08" rgba="0.5 0.3 0.1 1"/>
                </body>
            </body>

            <!-- hotpink Leg -->
            <body name="sphere2" pos="-0.15 0.1 0.1" euler="0 90 0">
                <joint name="sphere2-1" pos="0 0 0.1" type="hinge" axis="0 1 0" range="-45 45"/>
                <geom type="box" size="0.03 0.1 0.1" rgba="1 0 0.6 1"/>
                <body pos="0 0 -0.18">
                    <joint name="sphere2-2" pos="0 0 0.08" type="hinge" axis="0 1 0" range="-45 45"/>
                    <geom type="cylinder" size="0.02 0.08" rgba="0.5 0.3 0.1 1"/>
                </body>
            </body>

            <!-- Green Leg -->
            <body name="sphere3" pos="0.15 -0.1 0.1" euler="0 -90 0">
                <joint name="sphere3-1" pos="0 0 0.1" type="hinge" axis="0 1 0" range="-45 45"/>
                <geom type="box" size="0.03 0.1 0.1" rgba="0 0.3 0.1 1"/>
                <body pos="0 0 -0.18">
                    <joint name="sphere3-2" pos="0 0 0.08" type="hinge" axis="0 1 0" range="-45 45"/>
                    <geom type="cylinder" size="0.02 0.08" rgba="0.5 0.3 0.1 1"/>
                </body>
            </body>

            <!-- Back Right Leg -->
            <body name="sphere4" pos="0.15 0.1 0.1" euler="0 -90 0">
                <joint name="sphere4-1" pos="0 0 0.1" type="hinge" axis="0 1 0" range="-45 45"/>
                <geom type="box" size="0.03 0.1 0.1" rgba="0 0 0.6 1"/>
                <body pos="0 0 -0.18">
                    <joint name="sphere4-2" pos="0 0 0.08" type="hinge" axis="0 1 0" range="-45 45"/>
                    <geom type="cylinder" size="0.02 0.08" rgba="0.5 0.3 0.1 1"/>
                </body>
            </body>
        </body>

    </worldbody>
    <actuator>
        <motor joint="leg1-1" name="fl1j"/>
        <motor joint="leg1-2" name="fl2j"/>
        <motor joint="leg3-1" name="bl1j"/>
        <motor joint="leg3-2" name="bl2j"/>
        <motor joint="leg2-1" name="fr1j"/>
        <motor joint="leg2-2" name="fr2j"/>
        <motor joint="leg4-1" name="br1j"/>
        <motor joint="leg4-2" name="br2j"/>
    </actuator>
</mujoco>