<mujoco>
    <option gravity="0 0 -50.81" />
    <worldbody>
        <light diffuse="0.8 0.8 0.8" pos="0 0 8" dir="0 0 -1" />
        <geom type="plane" size="3 3 0.1" rgba="1 1 1 1" />
        
        <body name="main_body" pos="0 0 2">
            <joint name="main_body" type="free" />
            <geom type="box" size="0.13 0.3 0.12" rgba="1 0 0 1" euler="90 0 90" mass="40" /> 
            
            <body name="leg1" pos="-0.27 -0.1 0.1" euler="0 90 0">
                <joint name="leg1-1" pos="0 0 0.14" type="hinge" axis="0 1 0" range="-45 45" />
                <geom type="cylinder" size="0.01 0.14" rgba="0 1 0.6 0.5" mass="10" />
                <body name="shank1" pos="0 0 -0.28">
                    <joint name="leg1-2" pos="0 0 0.14" type="hinge" axis="0 1 0" range="-90 -70" />
                    <geom type="cylinder" size="0.01 0.25423962741603295" rgba="0.5 0.3 0.1 1" mass="30" />
                </body>
            </body>

            
            <body name="leg2" pos="-0.30000000000000004 0.1 0.1" euler="0 90 0">
                <joint name="leg2-1" pos="0 0 0.17" type="hinge" axis="0 1 0" range="-45 45" />
                <geom type="cylinder" size="0.01 0.17" rgba="1 0 0.6 1" mass="10" />
                <body name="shank2" pos="0 0 -0.34">
                    <joint name="leg2-2" pos="0 0 0.17" type="hinge" axis="0 1 0" range="-90 -70" />
                    <geom type="cylinder" size="0.01 0.30871954757661146" rgba="0.5 0.3 0.1 1" mass="30" />
                </body>
            </body>

            
            <body name="leg3" pos="0.23 -0.1 0.1" euler="0 -90 0">
                <joint name="leg3-1" pos="0 0 0.1" type="hinge" axis="0 1 0" range="-45 45" />
                <geom type="cylinder" size="0.02 0.1" rgba="0 0.3 0.1 1" mass="10" />
                <body name="shank3" pos="0 0 -0.2">
                    <joint name="leg3-2" pos="0 0 0.1" type="hinge" axis="0 1 0" range="70 90" />
                    <geom type="cylinder" size="0.02 0.1" rgba="0.5 0.3 0.1 1" mass="30" />
                </body>
            </body>

            
            <body name="leg4" pos="0.28 0.1 0.1" euler="0 -90 0">
                <joint name="leg4-1" pos="0 0 0.15" type="hinge" axis="0 1 0" range="-45 45" />
                <geom type="cylinder" size="0.01 0.15" rgba="0 0 0.6 1" mass="10" />
                <body name="shank4" pos="0 0 -0.3">
                    <joint name="leg4-2" pos="0 0 0.15" type="hinge" axis="0 1 0" range="70 90" />
                    <geom type="cylinder" size="0.01 0.15" rgba="0.5 0.3 0.1 1" mass="30" />
                </body>
            </body>
        </body>

    </worldbody>
    <actuator>
        <motor joint="leg1-1" name="fl1j" />
        <motor joint="leg1-2" name="fl2j" />
        <motor joint="leg3-1" name="bl1j" />
        <motor joint="leg3-2" name="bl2j" />
        <motor joint="leg2-1" name="fr1j" />
        <motor joint="leg2-2" name="fr2j" />
        <motor joint="leg4-1" name="br1j" />
        <motor joint="leg4-2" name="br2j" />
    </actuator>
</mujoco>